<?xml version="1.0" encoding="utf-8"?>
<!-- This URDF was automatically created by SolidWorks to URDF Exporter! Originally created by Stephen Brawner (brawner@gmail.com) 
     Commit Version: 1.6.0-4-g7f85cfe  Build Version: 1.6.7995.38578
     For more information, please see http://wiki.ros.org/sw_urdf_exporter -->
<robot
  name="a1y">
  <link
    name="base_link">
    <inertial>
      <origin
        xyz="0.00303246421307354 -0.000695340443194854 0.0297996781638517"
        rpy="0 0 0" />
      <mass
        value="0.786" />
      <inertia
        ixx="0.000209631286775999"
        ixy="1.3987766340865E-06"
        ixz="5.68764766805313E-06"
        iyy="0.000199785107628426"
        iyz="-3.65982104907021E-06"
        izz="0.000237444184695321" />
    </inertial>
    <visual>
      <origin
        xyz="0 0 0"
        rpy="0 0 0" />
      <geometry>
        <mesh
          filename="package://a1y/meshes/base_link.STL" />
      </geometry>
      <material
        name="">
        <color
          rgba="0.792156862745098 0.819607843137255 0.933333333333333 1" />
      </material>
    </visual>
    <collision>
      <origin
        xyz="0 0 0"
        rpy="0 0 0" />
      <geometry>
        <mesh
          filename="package://a1y/meshes/base_link.STL" />
      </geometry>
    </collision>
  </link>
  <link
    name="arm_link1">
    <inertial>
      <origin
        xyz="4.1065175135883E-07 -0.00198628171247454 0.0468863413356551"
        rpy="0 0 0" />
      <mass
        value="0.839" />
      <inertia
        ixx="0.000224135392915726"
        ixy="-1.28206810172038E-09"
        ixz="7.50235402650185E-09"
        iyy="0.00026979982869931"
        iyz="7.49527197322758E-09"
        izz="0.000218724360467532" />
    </inertial>
    <visual>
      <origin
        xyz="0 0 0"
        rpy="0 0 0" />
      <geometry>
        <mesh
          filename="package://a1y/meshes/arm_link1.STL" />
      </geometry>
      <material
        name="">
        <color
          rgba="0.823529411764706 0.823529411764706 1 1" />
      </material>
    </visual>
    <collision>
      <origin
        xyz="0 0 0"
        rpy="0 0 0" />
      <geometry>
        <mesh
          filename="package://a1y/meshes/arm_link1.STL" />
      </geometry>
    </collision>
  </link>
  <joint
    name="arm_joint1"
    type="revolute">
    <origin
      xyz="0 0 0.08605"
      rpy="0 0 0" />
    <parent
      link="base_link" />
    <child
      link="arm_link1" />
    <axis
      xyz="0 0 1" />
    <limit
      lower="-2.879795"
      upper="2.879795"
      effort="27"
      velocity="10.4720" />
  </joint>
  <link
    name="arm_link2">
    <inertial>
      <origin
        xyz="-0.122673818397923 -0.0295401461831619 0.00364838977156251"
        rpy="0 0 0" />
      <mass
        value="1.09" />
      <inertia
        ixx="0.000388311522528777"
        ixy="-2.18086613093501E-05"
        ixz="8.77434895649448E-06"
        iyy="0.00274683151904258"
        iyz="1.19756607314247E-06"
        izz="0.00278055331308976" />
    </inertial>
    <visual>
      <origin
        xyz="0 0 0"
        rpy="0 0 0" />
      <geometry>
        <mesh
          filename="package://a1y/meshes/arm_link2.STL" />
      </geometry>
      <material
        name="">
        <color
          rgba="0.823529411764706 0.823529411764706 1 1" />
      </material>
    </visual>
    <collision>
      <origin
        xyz="0 0 0"
        rpy="0 0 0" />
      <geometry>
        <mesh
          filename="package://a1y/meshes/arm_link2.STL" />
      </geometry>
    </collision>
  </link>
  <joint
    name="arm_joint2"
    type="revolute">
    <origin
      xyz="0 0.03075 0.04925"
      rpy="0 0 0" />
    <parent
      link="arm_link1" />
    <child
      link="arm_link2" />
    <axis
      xyz="0 1 0" />
    <limit
      lower="0"
      upper="3.1416"
      effort="50"
      velocity="12.5664" />
  </joint>
  <link
    name="arm_link3">
    <inertial>
      <origin
        xyz="0.0795681449160072 -0.0327357454565678 0.065177920553168"
        rpy="0 0 0" />
      <mass
        value="0.762" />
      <inertia
        ixx="0.000282703505875711"
        ixy="-4.06256349285171E-06"
        ixz="-7.63228373259732E-05"
        iyy="0.000329835410245831"
        iyz="-1.03493005263955E-05"
        izz="0.000237652038430906" />
    </inertial>
    <visual>
      <origin
        xyz="0 0 0"
        rpy="0 0 0" />
      <geometry>
        <mesh
          filename="package://a1y/meshes/arm_link3.STL" />
      </geometry>
      <material
        name="">
        <color
          rgba="0.823529411764706 0.823529411764706 1 1" />
      </material>
    </visual>
    <collision>
      <origin
        xyz="0 0 0"
        rpy="0 0 0" />
      <geometry>
        <mesh
          filename="package://a1y/meshes/arm_link3.STL" />
      </geometry>
    </collision>
  </link>
  <joint
    name="arm_joint3"
    type="revolute">
    <origin
      xyz="-0.3 0.00024449 0"
      rpy="0 0 0" />
    <parent
      link="arm_link2" />
    <child
      link="arm_link3" />
    <axis
      xyz="0 1 0" />
    <limit
      lower="-3.316127"
      upper="0"
      effort="27"
      velocity="10.4720" />
  </joint>
  <link
    name="arm_link4">
    <inertial>
      <origin
        xyz="0.0388578803222686 0.000937806543809841 -1.15721572034322E-05"
        rpy="0 0 0" />
      <mass
        value="0.353" />
      <inertia
        ixx="5.97701758868814E-05"
        ixy="-6.87774799668449E-10"
        ixz="-2.14372946639157E-10"
        iyy="6.0587917049985E-05"
        iyz="-5.98401601618766E-11"
        izz="5.98342278178533E-05" />
    </inertial>
    <visual>
      <origin
        xyz="0 0 0"
        rpy="0 0 0" />
      <geometry>
        <mesh
          filename="package://a1y/meshes/arm_link4.STL" />
      </geometry>
      <material
        name="">
        <color
          rgba="0.823529411764706 0.823529411764706 1 1" />
      </material>
    </visual>
    <collision>
      <origin
        xyz="0 0 0"
        rpy="0 0 0" />
      <geometry>
        <mesh
          filename="package://a1y/meshes/arm_link4.STL" />
      </geometry>
    </collision>
  </link>
  <joint
    name="arm_joint4"
    type="revolute">
    <origin
      xyz="0.1544 -0.030998 0.075485"
      rpy="0 0 0" />
    <parent
      link="arm_link3" />
    <child
      link="arm_link4" />
    <axis
      xyz="1 0 0" />
    <limit
      lower="-2.879795"
      upper="2.879795"
      effort="14"
      velocity="32.9867" />
  </joint>
  <link
    name="arm_link5">
    <inertial>
      <origin
        xyz="0.0526293728146609 -0.0197387756630963 7.38547745043894E-06"
        rpy="0 0 0" />
      <mass
        value="0.366" />
      <inertia
        ixx="5.87226827172217E-05"
        ixy="3.94835644387525E-09"
        ixz="-1.57113932950695E-12"
        iyy="6.96559934519655E-05"
        iyz="7.55674102061766E-09"
        izz="6.85055623583414E-05" />
    </inertial>
    <visual>
      <origin
        xyz="0 0 0"
        rpy="0 0 0" />
      <geometry>
        <mesh
          filename="package://a1y/meshes/arm_link5.STL" />
      </geometry>
      <material
        name="">
        <color
          rgba="0.823529411764706 0.823529411764706 1 1" />
      </material>
    </visual>
    <collision>
      <origin
        xyz="0 0 0"
        rpy="0 0 0" />
      <geometry>
        <mesh
          filename="package://a1y/meshes/arm_link5.STL" />
      </geometry>
    </collision>
  </link>
  <joint
    name="arm_joint5"
    type="revolute">
    <origin
      xyz="0.0418 0.023501 0"
      rpy="0 0 0" />
    <parent
      link="arm_link4" />
    <child
      link="arm_link5" />
    <axis
      xyz="0 1 0" />
    <limit
      lower="-1.832597"
      upper="1.832597"
      effort="14"
      velocity="32.9867" />
  </joint>
  <link
    name="arm_link6">
    <inertial>
      <origin
        xyz="0.00709944781467154 1.26586535489642E-07 -3.8262881471296E-05"
        rpy="0 0 0" />
      <mass
        value="0.031" />
      <inertia
        ixx="3.44528457425794E-06"
        ixy="2.98138934982256E-11"
        ixz="-1.26128084918303E-09"
        iyy="1.82573408455416E-06"
        iyz="1.17092872453752E-14"
        izz="1.8173151968758E-06" />
    </inertial>
    <visual>
      <origin
        xyz="0 0 0"
        rpy="0 0 0" />
      <geometry>
        <mesh
          filename="package://a1y/meshes/arm_link6.STL" />
      </geometry>
      <material
        name="">
        <color
          rgba="0.823529411764706 0.823529411764706 1 1" />
      </material>
    </visual>
    <collision>
      <origin
        xyz="0 0 0"
        rpy="0 0 0" />
      <geometry>
        <mesh
          filename="package://a1y/meshes/arm_link6.STL" />
      </geometry>
    </collision>
  </link>
  <joint
    name="arm_joint6"
    type="revolute">
    <origin
      xyz="0.081 -0.023499 0"
      rpy="0 0 0" />
    <parent
      link="arm_link5" />
    <child
      link="arm_link6" />
    <axis
      xyz="1 0 0" />
    <limit
      lower="-2.879795"
      upper="2.879795"
      effort="14"
      velocity="32.9867" />
  </joint>
  <link
    name="gripper_link">
    <inertial>
      <origin
        xyz="-0.0311072379463468 -5.32126034905504E-07 -9.19980751579175E-08"
        rpy="0 0 0" />
      <mass
        value="0.604" />
      <inertia
        ixx="0.00017587895693059"
        ixy="1.38739918178544E-09"
        ixz="1.28476385950592E-09"
        iyy="9.86355058862358E-05"
        iyz="-8.18608543121037E-08"
        izz="0.000165120403698736" />
    </inertial>
    <visual>
      <origin
        xyz="0 0 0"
        rpy="0 0 0" />
      <geometry>
        <mesh
          filename="package://a1y/meshes/gripper_link.STL" />
      </geometry>
      <material
        name="">
        <color
          rgba="0.823529411764706 0.823529411764706 1 1" />
      </material>
    </visual>
    <collision>
      <origin
        xyz="0 0 0"
        rpy="0 0 0" />
      <geometry>
        <mesh
          filename="package://a1y/meshes/gripper_link.STL" />
      </geometry>
    </collision>
  </link>
  <joint
    name="gripper_joint"
    type="fixed">
    <origin
      xyz="0.08165 0 0"
      rpy="0 0 0" />
    <parent
      link="arm_link6" />
    <child
      link="gripper_link" />
    <axis
      xyz="0 0 0" />
  </joint>
  <link
    name="gripper_finger_link1">
    <inertial>
      <origin
        xyz="-0.0195892566606875 -0.0151140214225836 0.00542244704455089"
        rpy="0 0 0" />
      <mass
        value="0.027" />
      <inertia
        ixx="2.4056694815471E-06"
        ixy="3.98931810903216E-07"
        ixz="5.12130822079716E-08"
        iyy="5.71084140803849E-06"
        iyz="6.19490405774933E-08"
        izz="6.48485512533118E-06" />
    </inertial>
    <visual>
      <origin
        xyz="0 0 0"
        rpy="0 0 0" />
      <geometry>
        <mesh
          filename="package://a1y/meshes/gripper_finger_link1.STL" />
      </geometry>
      <material
        name="">
        <color
          rgba="0.823529411764706 0.823529411764706 1 1" />
      </material>
    </visual>
    <collision>
      <origin
        xyz="0 0 0"
        rpy="0 0 0" />
      <geometry>
        <mesh
          filename="package://a1y/meshes/gripper_finger_link1.STL" />
      </geometry>
    </collision>
  </link>
  <joint
    name="gripper_finger_joint1"
    type="prismatic">
    <origin
      xyz="0.03689 0.013454 0.00012065"
      rpy="0 0 0" />
    <parent
      link="gripper_link" />
    <child
      link="gripper_finger_link1" />
    <axis
      xyz="0 1 0" />
    <limit
      lower="0"
      upper="0.05"
      effort="100"
      velocity="0.25" />
  </joint>
  <link
    name="gripper_finger_link2">
    <inertial>
      <origin
        xyz="-0.0195898119754071 0.0151133016660799 -0.00542244700767924"
        rpy="0 0 0" />
      <mass
        value="0.027" />
      <inertia
        ixx="2.40569880083347E-06"
        ixy="-3.99053247972178E-07"
        ixz="-5.12153506189465E-08"
        iyy="5.71081208855091E-06"
        iyz="6.19471596215801E-08"
        izz="6.48485512551603E-06" />
    </inertial>
    <visual>
      <origin
        xyz="0 0 0"
        rpy="0 0 0" />
      <geometry>
        <mesh
          filename="package://a1y/meshes/gripper_finger_link2.STL" />
      </geometry>
      <material
        name="">
        <color
          rgba="0.823529411764706 0.823529411764706 1 1" />
      </material>
    </visual>
    <collision>
      <origin
        xyz="0 0 0"
        rpy="0 0 0" />
      <geometry>
        <mesh
          filename="package://a1y/meshes/gripper_finger_link2.STL" />
      </geometry>
    </collision>
  </link>
  <joint
    name="gripper_finger_joint2"
    type="prismatic">
    <origin
      xyz="0.03689 -0.013452 -0.00012065"
      rpy="0 0 0" />
    <parent
      link="gripper_link" />
    <child
      link="gripper_finger_link2" />
    <axis
      xyz="0 1 0" />
    <limit
      lower="-0.05"
      upper="0"
      effort="100"
      velocity="0.25" />
  </joint>
</robot>